import Assignment from './repo'
import Response from '../../utils/Responses';

exports.create = async (req, res) => {
    try {
        const {
            title, assignedClass, subject
        } = req.body;
        const teacher = req.user._id

        Assignment.create(title, assignedClass, subject, teacher)
        .then(results => {
            Response.Success(res, 200, "created successfully", results);
        })
        .catch(err => {
            console.log(err);
            Response.InternalServerError(res, "We are having issues! please try again soon");
        });

    } catch (error) {
        console.log(error);
        Response.InternalServerError(res, "We are having issues! please try again soon");
    }
    
}

exports.update = async (req, res) => {
    try {
        const assignmentId = req.params.assignmentId;
        const {
            title
        } = req.body;
        Assignment.update(assignmentId, title)
            .then(results => {
                Response.Success(res, 200, "updated successfully", results);
            })
            .catch(err => {
                console.log(err);
                Response.InternalServerError(res, "We are having issues! please try again soon");
            });

    } catch (error) {
        console.log(error);
        Response.InternalServerError(res, "We are having issues! please try again soon");
    }
    
}

exports.getAllClassSubjectAssignmentes = async (req, res) => {
    try {

        const classId = req.params.classId;
        const subjectId = req.params.subjectId
        Assignment.getAllClassSubjectAssignmentes(classId, subjectId)
            .then(results => {
                Response.Success(res, 200, "queried successfully", results);
            })
            .catch(err => {
                console.log(err);
                Response.InternalServerError(res, "We are having issues! please try again soon");
            });

    } catch (error) {
        console.log(error);
        Response.InternalServerError(res, "We are having issues! please try again soon");
    }
    
}


exports.getOneAssignment = async (req, res) => {
    try {
        const assignmentId = req.params.assignmentId;

        Assignment.getOneAssignment(assignmentId)
            .then(results => {
                Response.Success(res, 200, "queried successfully", results);
            })
            .catch(err => {
                console.log(err);
                Response.InternalServerError(res, "We are having issues! please try again soon");
            });

    } catch (error) {
        console.log(error);
        Response.InternalServerError(res, "We are having issues! please try again soon");
    }
    
}

exports.delete = async (req, res) => {
    try {
        const assignmentId = req.params.assignmentId;
        
        Assignment.delete(assignmentId)
            .then(results => {
                Response.Success(res, 200, "deleted successfully", results);
            })
            .catch(err => {
                console.log(err);
                Response.InternalServerError(res, "We are having issues! please try again soon");
            });

    } catch (error) {
        console.log(error);
        Response.InternalServerError(res, "We are having issues! please try again soon");
    }
    
}