import Combination from './repo'
import Response from '../../utils/Responses';

exports.create = async (req, res) => {
    try {
        const {
            name
        } = req.body;

        Combination.create(name)
        .then(results => {
            Response.Success(res, 200, "created successfully", results);
        })
        .catch(err => {
            console.log(err);
            Response.InternalServerError(res, "We are having issues! please try again soon");
        });

    } catch (error) {
        console.log(error);
        Response.InternalServerError(res, "We are having issues! please try again soon");
    }
    
}

exports.update = async (req, res) => {
    try {
        const combinationId = req.params.combinationId;
        const {
            name
        } = req.body;
        Combination.update(combinationId, name)
            .then(results => {
                Response.Success(res, 200, "updated successfully", results);
            })
            .catch(err => {
                console.log(err);
                Response.InternalServerError(res, "We are having issues! please try again soon");
            });

    } catch (error) {
        console.log(error);
        Response.InternalServerError(res, "We are having issues! please try again soon");
    }
    
}

exports.getAllCombinations = async (req, res) => {
    try {

        Combination.getAllCombinations()
            .then(results => {
                Response.Success(res, 200, "queried successfully", results);
            })
            .catch(err => {
                console.log(err);
                Response.InternalServerError(res, "We are having issues! please try again soon");
            });

    } catch (error) {
        console.log(error);
        Response.InternalServerError(res, "We are having issues! please try again soon");
    }
    
}


exports.getOneCombination = async (req, res) => {
    try {
        const combinationId = req.params.combinationId;

        Combination.getOneCombination(combinationId)
            .then(results => {
                Response.Success(res, 200, "queried successfully", results);
            })
            .catch(err => {
                console.log(err);
                Response.InternalServerError(res, "We are having issues! please try again soon");
            });

    } catch (error) {
        console.log(error);
        Response.InternalServerError(res, "We are having issues! please try again soon");
    }
    
}

exports.delete = async (req, res) => {
    try {
        const combinationId = req.params.combinationId;
        
        Combination.delete(combinationId)
            .then(results => {
                Response.Success(res, 200, "deleted successfully", results);
            })
            .catch(err => {
                console.log(err);
                Response.InternalServerError(res, "We are having issues! please try again soon");
            });

    } catch (error) {
        console.log(error);
        Response.InternalServerError(res, "We are having issues! please try again soon");
    }
    
}