import StudentLeave from './repo'
import Response from '../../utils/Responses';

exports.create = async (req, res) => {
    try {
        const {
            student,
            reason,
            checkout
        } = req.body;
        const checkedoutBy = req.user._id

        StudentLeave.create(student, reason, checkout, checkedoutBy)
        .then(results => {
            Response.Success(res, 200, "created successfully", results);
        })
        .catch(err => {
            console.log(err);
            Response.InternalServerError(res, "We are having issues! please try again soon");
        });

    } catch (error) {
        console.log(error);
        Response.InternalServerError(res, "We are having issues! please try again soon");
    }
    
}

exports.update = async (req, res) => {
    try {
        const studentLeaveId = req.params.studentLeaveId;
        const checkedinBy = req.user._id
        const {
            checkin
        } = req.body;
        StudentLeave.update(studentLeaveId, checkin, checkedinBy)
            .then(results => {
                Response.Success(res, 200, "updated successfully", results);
            })
            .catch(err => {
                console.log(err);
                Response.InternalServerError(res, "We are having issues! please try again soon");
            });

    } catch (error) {
        console.log(error);
        Response.InternalServerError(res, "We are having issues! please try again soon");
    }
    
}

exports.getAllStudentLeaves = async (req, res) => {
    try {

        StudentLeave.getAllStudentLeaves()
            .then(results => {
                Response.Success(res, 200, "queried successfully", results);
            })
            .catch(err => {
                console.log(err);
                Response.InternalServerError(res, "We are having issues! please try again soon");
            });

    } catch (error) {
        console.log(error);
        Response.InternalServerError(res, "We are having issues! please try again soon");
    }
    
}


exports.getOneStudentLeave = async (req, res) => {
    try {
        const studentLeaveId = req.params.studentLeaveId;

        StudentLeave.getOneStudentLeave(studentLeaveId)
            .then(results => {
                Response.Success(res, 200, "queried successfully", results);
            })
            .catch(err => {
                console.log(err);
                Response.InternalServerError(res, "We are having issues! please try again soon");
            });

    } catch (error) {
        console.log(error);
        Response.InternalServerError(res, "We are having issues! please try again soon");
    }
    
}

exports.delete = async (req, res) => {
    try {
        const studentLeaveId = req.params.studentLeaveId;
        
        StudentLeave.delete(studentLeaveId)
            .then(results => {
                Response.Success(res, 200, "deleted successfully", results);
            })
            .catch(err => {
                console.log(err);
                Response.InternalServerError(res, "We are having issues! please try again soon");
            });

    } catch (error) {
        console.log(error);
        Response.InternalServerError(res, "We are having issues! please try again soon");
    }
    
}