import Plan from './repo'
import Response from '../../../utils/Responses';

exports.create = async (req, res) => {
    try {
        const {
            name,
            unit,
            course
        } = req.body;

        Plan.create(name, unit, course)
        .then(results => {
            Response.Success(res, 200, "created successfully", results);
        })
        .catch(err => {
            console.log(err);
            Response.InternalServerError(res, "We are having issues! please try again soon");
        });

    } catch (error) {
        console.log(error);
        Response.InternalServerError(res, "We are having issues! please try again soon");
    }
    
}

exports.update = async (req, res) => {
    try {
        const planId = req.params.planId;
        const {
            name
        } = req.body;
        Plan.update(planId, name)
            .then(results => {
                Response.Success(res, 200, "updated successfully", results);
            })
            .catch(err => {
                console.log(err);
                Response.InternalServerError(res, "We are having issues! please try again soon");
            });

    } catch (error) {
        console.log(error);
        Response.InternalServerError(res, "We are having issues! please try again soon");
    }
    
}

exports.getCoursePlan = async (req, res) => {
    try {

        const courseId = req.params.courseId;
        Plan.getAllCoursePlan(courseId)
            .then(results => {
                Response.Success(res, 200, "queried successfully", results);
            })
            .catch(err => {
                console.log(err);
                Response.InternalServerError(res, "We are having issues! please try again soon");
            });

    } catch (error) {
        console.log(error);
        Response.InternalServerError(res, "We are having issues! please try again soon");
    }
    
}


exports.getOnePlan = async (req, res) => {
    try {
        const planId = req.params.planId;

        Plan.getOnePlan(planId)
            .then(results => {
                Response.Success(res, 200, "queried successfully", results);
            })
            .catch(err => {
                console.log(err);
                Response.InternalServerError(res, "We are having issues! please try again soon");
            });

    } catch (error) {
        console.log(error);
        Response.InternalServerError(res, "We are having issues! please try again soon");
    }
    
}

exports.delete = async (req, res) => {
    try {
        const planId = req.params.planId;
        
        Plan.delete(planId)
            .then(results => {
                Response.Success(res, 200, "deleted successfully", results);
            })
            .catch(err => {
                console.log(err);
                Response.InternalServerError(res, "We are having issues! please try again soon");
            });

    } catch (error) {
        console.log(error);
        Response.InternalServerError(res, "We are having issues! please try again soon");
    }
    
}