import Guest from './repo'
import Response from '../../utils/Responses';

exports.create = async (req, res) => {
    try {
        const {
            firstName, 
            lastName,
            reason,
            checkin
        } = req.body;
        const checkedinBy = req.user._id
        const school = req.user.school

        Guest.create(firstName, lastName, reason, checkin, checkedinBy, school)
        .then(results => {
            Response.Success(res, 200, "created successfully", results);
        })
        .catch(err => {
            console.log(err);
            Response.InternalServerError(res, "We are having issues! please try again soon");
        });

    } catch (error) {
        console.log(error);
        Response.InternalServerError(res, "We are having issues! please try again soon");
    }
    
}

exports.update = async (req, res) => {
    try {
        const guestId = req.params.guestId;
        const checkedoutBy = req.user._id
        const {
            checkout
        } = req.body;
        Guest.update(guestId, checkout, checkedoutBy)
            .then(results => {
                Response.Success(res, 200, "updated successfully", results);
            })
            .catch(err => {
                console.log(err);
                Response.InternalServerError(res, "We are having issues! please try again soon");
            });

    } catch (error) {
        console.log(error);
        Response.InternalServerError(res, "We are having issues! please try again soon");
    }
    
}

exports.getAllSchoolGuests = async (req, res) => {
    try {
        const school = req.params.school;
        Guest.getAllSchoolGuests(school)
            .then(results => {
                Response.Success(res, 200, "queried successfully", results);
            })
            .catch(err => {
                console.log(err);
                Response.InternalServerError(res, "We are having issues! please try again soon");
            });

    } catch (error) {
        console.log(error);
        Response.InternalServerError(res, "We are having issues! please try again soon");
    }
    
}


exports.getOneGuest = async (req, res) => {
    try {
        const guestId = req.params.guestId;

        Guest.getOneGuest(guestId)
            .then(results => {
                Response.Success(res, 200, "queried successfully", results);
            })
            .catch(err => {
                console.log(err);
                Response.InternalServerError(res, "We are having issues! please try again soon");
            });

    } catch (error) {
        console.log(error);
        Response.InternalServerError(res, "We are having issues! please try again soon");
    }
    
}

exports.delete = async (req, res) => {
    try {
        const guestId = req.params.guestId;
        
        Guest.delete(guestId)
            .then(results => {
                Response.Success(res, 200, "deleted successfully", results);
            })
            .catch(err => {
                console.log(err);
                Response.InternalServerError(res, "We are having issues! please try again soon");
            });

    } catch (error) {
        console.log(error);
        Response.InternalServerError(res, "We are having issues! please try again soon");
    }
    
}