import Subject from './repo'
import Response from '../../../utils/Responses';

exports.create = async (req, res) => {
    try {
        const {
            name
        } = req.body;

        Subject.create(name)
        .then(results => {
            Response.Success(res, 200, "created successfully", results);
        })
        .catch(err => {
            console.log(err);
            Response.InternalServerError(res, "We are having issues! please try again soon");
        });

    } catch (error) {
        console.log(error);
        Response.InternalServerError(res, "We are having issues! please try again soon");
    }
    
}

exports.update = async (req, res) => {
    try {
        const subjectId = req.params.subjectId;
        const {
            name
        } = req.body;
        Subject.update(subjectId, name)
            .then(results => {
                Response.Success(res, 200, "updated successfully", results);
            })
            .catch(err => {
                console.log(err);
                Response.InternalServerError(res, "We are having issues! please try again soon");
            });

    } catch (error) {
        console.log(error);
        Response.InternalServerError(res, "We are having issues! please try again soon");
    }
    
}

exports.getAllSubjects = async (req, res) => {
    try {

        Subject.getAllSubjects()
            .then(results => {
                Response.Success(res, 200, "queried successfully", results);
            })
            .catch(err => {
                console.log(err);
                Response.InternalServerError(res, "We are having issues! please try again soon");
            });

    } catch (error) {
        console.log(error);
        Response.InternalServerError(res, "We are having issues! please try again soon");
    }
    
}


exports.getOneSubject = async (req, res) => {
    try {
        const subjectId = req.params.subjectId;

        Subject.getOneSubject(subjectId)
            .then(results => {
                Response.Success(res, 200, "queried successfully", results);
            })
            .catch(err => {
                console.log(err);
                Response.InternalServerError(res, "We are having issues! please try again soon");
            });

    } catch (error) {
        console.log(error);
        Response.InternalServerError(res, "We are having issues! please try again soon");
    }
    
}

exports.delete = async (req, res) => {
    try {
        const subjectId = req.params.subjectId;
        
        Subject.delete(subjectId)
            .then(results => {
                Response.Success(res, 200, "deleted successfully", results);
            })
            .catch(err => {
                console.log(err);
                Response.InternalServerError(res, "We are having issues! please try again soon");
            });

    } catch (error) {
        console.log(error);
        Response.InternalServerError(res, "We are having issues! please try again soon");
    }
    
}